[2025-05-10 17:20:54,595] [INFO] [real_accelerator.py:239:get_accelerator] Setting ds_accelerator to cuda (auto detect)
[2025-05-10 17:21:03,790] [INFO] [real_accelerator.py:239:get_accelerator] Setting ds_accelerator to cuda (auto detect)
[2025-05-10 17:21:03,791] [INFO] [real_accelerator.py:239:get_accelerator] Setting ds_accelerator to cuda (auto detect)
[2025-05-10 17:21:03,792] [INFO] [real_accelerator.py:239:get_accelerator] Setting ds_accelerator to cuda (auto detect)
You are attempting to use Flash Attention 2.0 with a model not initialized on GPU. Make sure to move the model to GPU after initializing it on CPU with `model.to('cuda')`.
You are attempting to use Flash Attention 2.0 with a model not initialized on GPU. Make sure to move the model to GPU after initializing it on CPU with `model.to('cuda')`.
You are attempting to use Flash Attention 2.0 with a model not initialized on GPU. Make sure to move the model to GPU after initializing it on CPU with `model.to('cuda')`.
Loading checkpoint shards:   0%|          | 0/4 [00:00<?, ?it/s]Loading checkpoint shards:   0%|          | 0/4 [00:00<?, ?it/s]Loading checkpoint shards:   0%|          | 0/4 [00:00<?, ?it/s]Loading checkpoint shards:  25%|██▌       | 1/4 [00:29<01:28, 29.36s/it]Loading checkpoint shards:  25%|██▌       | 1/4 [00:29<01:28, 29.38s/it]Loading checkpoint shards:  25%|██▌       | 1/4 [00:29<01:28, 29.39s/it]Loading checkpoint shards:  50%|█████     | 2/4 [01:07<01:08, 34.30s/it]Loading checkpoint shards:  50%|█████     | 2/4 [01:07<01:08, 34.30s/it]Loading checkpoint shards:  50%|█████     | 2/4 [01:07<01:08, 34.31s/it]Loading checkpoint shards:  75%|███████▌  | 3/4 [01:44<00:35, 35.66s/it]Loading checkpoint shards:  75%|███████▌  | 3/4 [01:44<00:35, 35.67s/it]Loading checkpoint shards:  75%|███████▌  | 3/4 [01:44<00:35, 35.68s/it]Loading checkpoint shards: 100%|██████████| 4/4 [02:11<00:00, 32.12s/it]Loading checkpoint shards: 100%|██████████| 4/4 [02:11<00:00, 32.78s/it]
Loading checkpoint shards: 100%|██████████| 4/4 [02:11<00:00, 32.14s/it]Loading checkpoint shards: 100%|██████████| 4/4 [02:11<00:00, 32.79s/it]
Loading checkpoint shards: 100%|██████████| 4/4 [02:11<00:00, 32.14s/it]Loading checkpoint shards: 100%|██████████| 4/4 [02:11<00:00, 32.79s/it]
Loading checkpoint shards:   0%|          | 0/2 [00:00<?, ?it/s]Loading checkpoint shards:   0%|          | 0/2 [00:00<?, ?it/s]Loading checkpoint shards:   0%|          | 0/2 [00:00<?, ?it/s]Loading checkpoint shards:  50%|█████     | 1/2 [00:44<00:44, 44.16s/it]Loading checkpoint shards:  50%|█████     | 1/2 [00:44<00:44, 44.17s/it]Loading checkpoint shards:  50%|█████     | 1/2 [00:44<00:44, 44.13s/it]Loading checkpoint shards: 100%|██████████| 2/2 [00:47<00:00, 20.04s/it]Loading checkpoint shards: 100%|██████████| 2/2 [00:47<00:00, 23.66s/it]
Loading checkpoint shards: 100%|██████████| 2/2 [00:47<00:00, 20.01s/it]Loading checkpoint shards: 100%|██████████| 2/2 [00:47<00:00, 23.63s/it]
Loading checkpoint shards: 100%|██████████| 2/2 [00:47<00:00, 20.05s/it]Loading checkpoint shards: 100%|██████████| 2/2 [00:47<00:00, 23.67s/it]
[2025-05-10 17:24:18,647] [INFO] [comm.py:669:init_distributed] cdb=None
[2025-05-10 17:24:18,647] [INFO] [comm.py:700:init_distributed] Initializing TorchBackend in DeepSpeed with backend nccl
[2025-05-10 17:24:18,649] [INFO] [comm.py:669:init_distributed] cdb=None
[2025-05-10 17:24:18,649] [INFO] [comm.py:669:init_distributed] cdb=None
[rank0]: Traceback (most recent call last):
[rank0]:   File "/gscratch/stf/lbc800/mistral-KD/train_scripts/GKD.py", line 82, in <module>
[rank0]:     trainer = GKDTrainer( #default collator set up is good for now
[rank0]:   File "/usr/local/lib/python3.10/dist-packages/trl/trainer/gkd_trainer.py", line 90, in __init__
[rank0]:     super().__init__(
[rank0]:   File "/usr/local/lib/python3.10/dist-packages/trl/trainer/sft_trainer.py", line 323, in __init__
[rank0]:     train_dataset = self._prepare_dataset(
[rank0]:   File "/usr/local/lib/python3.10/dist-packages/trl/trainer/gkd_trainer.py", line 157, in _prepare_dataset
[rank0]:     dataset = dataset.add_column("_messages", dataset["messages"])
[rank0]:   File "/usr/local/lib/python3.10/dist-packages/datasets/arrow_dataset.py", line 2777, in __getitem__
[rank0]:     return self._getitem(key)
[rank0]:   File "/usr/local/lib/python3.10/dist-packages/datasets/arrow_dataset.py", line 2761, in _getitem
[rank0]:     pa_subtable = query_table(self._data, key, indices=self._indices)
[rank0]:   File "/usr/local/lib/python3.10/dist-packages/datasets/formatting/formatting.py", line 604, in query_table
[rank0]:     _check_valid_column_key(key, table.column_names)
[rank0]:   File "/usr/local/lib/python3.10/dist-packages/datasets/formatting/formatting.py", line 541, in _check_valid_column_key
[rank0]:     raise KeyError(f"Column {key} not in the dataset. Current columns in the dataset: {columns}")
[rank0]: KeyError: "Column messages not in the dataset. Current columns in the dataset: ['input_ids', 'attention_mask', 'labels', 'prompt', 'prompt_input_ids', 'prompt_attention_mask']"
[rank1]: Traceback (most recent call last):
[rank1]:   File "/gscratch/stf/lbc800/mistral-KD/train_scripts/GKD.py", line 82, in <module>
[rank1]:     trainer = GKDTrainer( #default collator set up is good for now
[rank1]:   File "/usr/local/lib/python3.10/dist-packages/trl/trainer/gkd_trainer.py", line 90, in __init__
[rank1]:     super().__init__(
[rank1]:   File "/usr/local/lib/python3.10/dist-packages/trl/trainer/sft_trainer.py", line 323, in __init__
[rank1]:     train_dataset = self._prepare_dataset(
[rank1]:   File "/usr/local/lib/python3.10/dist-packages/trl/trainer/gkd_trainer.py", line 157, in _prepare_dataset
[rank1]:     dataset = dataset.add_column("_messages", dataset["messages"])
[rank1]:   File "/usr/local/lib/python3.10/dist-packages/datasets/arrow_dataset.py", line 2777, in __getitem__
[rank1]:     return self._getitem(key)
[rank1]:   File "/usr/local/lib/python3.10/dist-packages/datasets/arrow_dataset.py", line 2761, in _getitem
[rank1]:     pa_subtable = query_table(self._data, key, indices=self._indices)
[rank1]:   File "/usr/local/lib/python3.10/dist-packages/datasets/formatting/formatting.py", line 604, in query_table
[rank1]:     _check_valid_column_key(key, table.column_names)
[rank1]:   File "/usr/local/lib/python3.10/dist-packages/datasets/formatting/formatting.py", line 541, in _check_valid_column_key
[rank1]:     raise KeyError(f"Column {key} not in the dataset. Current columns in the dataset: {columns}")
[rank1]: KeyError: "Column messages not in the dataset. Current columns in the dataset: ['input_ids', 'attention_mask', 'labels', 'prompt', 'prompt_input_ids', 'prompt_attention_mask']"
[rank2]: Traceback (most recent call last):
[rank2]:   File "/gscratch/stf/lbc800/mistral-KD/train_scripts/GKD.py", line 82, in <module>
[rank2]:     trainer = GKDTrainer( #default collator set up is good for now
[rank2]:   File "/usr/local/lib/python3.10/dist-packages/trl/trainer/gkd_trainer.py", line 90, in __init__
[rank2]:     super().__init__(
[rank2]:   File "/usr/local/lib/python3.10/dist-packages/trl/trainer/sft_trainer.py", line 323, in __init__
[rank2]:     train_dataset = self._prepare_dataset(
[rank2]:   File "/usr/local/lib/python3.10/dist-packages/trl/trainer/gkd_trainer.py", line 157, in _prepare_dataset
[rank2]:     dataset = dataset.add_column("_messages", dataset["messages"])
[rank2]:   File "/usr/local/lib/python3.10/dist-packages/datasets/arrow_dataset.py", line 2777, in __getitem__
[rank2]:     return self._getitem(key)
[rank2]:   File "/usr/local/lib/python3.10/dist-packages/datasets/arrow_dataset.py", line 2761, in _getitem
[rank2]:     pa_subtable = query_table(self._data, key, indices=self._indices)
[rank2]:   File "/usr/local/lib/python3.10/dist-packages/datasets/formatting/formatting.py", line 604, in query_table
[rank2]:     _check_valid_column_key(key, table.column_names)
[rank2]:   File "/usr/local/lib/python3.10/dist-packages/datasets/formatting/formatting.py", line 541, in _check_valid_column_key
[rank2]:     raise KeyError(f"Column {key} not in the dataset. Current columns in the dataset: {columns}")
[rank2]: KeyError: "Column messages not in the dataset. Current columns in the dataset: ['input_ids', 'attention_mask', 'labels', 'prompt', 'prompt_input_ids', 'prompt_attention_mask']"
[rank0]:[W510 17:24:20.570432785 ProcessGroupNCCL.cpp:1496] Warning: WARNING: destroy_process_group() was not called before program exit, which can leak resources. For more info, please see https://pytorch.org/docs/stable/distributed.html#shutdown (function operator())
W0510 17:24:29.017000 5127 torch/distributed/elastic/multiprocessing/api.py:897] Sending process 5317 closing signal SIGTERM
W0510 17:24:29.017000 5127 torch/distributed/elastic/multiprocessing/api.py:897] Sending process 5318 closing signal SIGTERM
E0510 17:24:29.156000 5127 torch/distributed/elastic/multiprocessing/api.py:869] failed (exitcode: 1) local_rank: 0 (pid: 5316) of binary: /usr/bin/python3
Traceback (most recent call last):
  File "/usr/local/bin/accelerate", line 8, in <module>
    sys.exit(main())
  File "/usr/local/lib/python3.10/dist-packages/accelerate/commands/accelerate_cli.py", line 50, in main
    args.func(args)
  File "/usr/local/lib/python3.10/dist-packages/accelerate/commands/launch.py", line 1196, in launch_command
    deepspeed_launcher(args)
  File "/usr/local/lib/python3.10/dist-packages/accelerate/commands/launch.py", line 878, in deepspeed_launcher
    distrib_run.run(args)
  File "/usr/local/lib/python3.10/dist-packages/torch/distributed/run.py", line 909, in run
    elastic_launch(
  File "/usr/local/lib/python3.10/dist-packages/torch/distributed/launcher/api.py", line 138, in __call__
    return launch_agent(self._config, self._entrypoint, list(args))
  File "/usr/local/lib/python3.10/dist-packages/torch/distributed/launcher/api.py", line 269, in launch_agent
    raise ChildFailedError(
torch.distributed.elastic.multiprocessing.errors.ChildFailedError: 
============================================================
/gscratch/stf/lbc800/mistral-KD/train_scripts/GKD.py FAILED
------------------------------------------------------------
Failures:
  <NO_OTHER_FAILURES>
------------------------------------------------------------
Root Cause (first observed failure):
[0]:
  time      : 2025-05-10_17:24:29
  host      : g3105.hyak.local
  rank      : 0 (local_rank: 0)
  exitcode  : 1 (pid: 5316)
  error_file: <N/A>
  traceback : To enable traceback see: https://pytorch.org/docs/stable/elastic/errors.html
============================================================
srun: error: g3105: task 0: Exited with exit code 1
