[2025-05-12 15:53:52,566] [INFO] [real_accelerator.py:239:get_accelerator] Setting ds_accelerator to cuda (auto detect)
Traceback (most recent call last):
  File "/usr/local/bin/accelerate", line 8, in <module>
    sys.exit(main())
  File "/usr/local/lib/python3.10/dist-packages/accelerate/commands/accelerate_cli.py", line 50, in main
    args.func(args)
  File "/usr/local/lib/python3.10/dist-packages/accelerate/commands/launch.py", line 1196, in launch_command
    deepspeed_launcher(args)
  File "/usr/local/lib/python3.10/dist-packages/accelerate/commands/launch.py", line 878, in deepspeed_launcher
    distrib_run.run(args)
  File "/usr/local/lib/python3.10/dist-packages/torch/distributed/run.py", line 909, in run
    elastic_launch(
  File "/usr/local/lib/python3.10/dist-packages/torch/distributed/launcher/api.py", line 138, in __call__
    return launch_agent(self._config, self._entrypoint, list(args))
  File "/usr/local/lib/python3.10/dist-packages/torch/distributed/launcher/api.py", line 260, in launch_agent
    result = agent.run()
  File "/usr/local/lib/python3.10/dist-packages/torch/distributed/elastic/metrics/api.py", line 137, in wrapper
    result = f(*args, **kwargs)
  File "/usr/local/lib/python3.10/dist-packages/torch/distributed/elastic/agent/server/api.py", line 711, in run
    result = self._invoke_run(role)
  File "/usr/local/lib/python3.10/dist-packages/torch/distributed/elastic/agent/server/api.py", line 864, in _invoke_run
    self._initialize_workers(self._worker_group)
  File "/usr/local/lib/python3.10/dist-packages/torch/distributed/elastic/metrics/api.py", line 137, in wrapper
    result = f(*args, **kwargs)
  File "/usr/local/lib/python3.10/dist-packages/torch/distributed/elastic/agent/server/api.py", line 683, in _initialize_workers
    self._rendezvous(worker_group)
  File "/usr/local/lib/python3.10/dist-packages/torch/distributed/elastic/metrics/api.py", line 137, in wrapper
    result = f(*args, **kwargs)
  File "/usr/local/lib/python3.10/dist-packages/torch/distributed/elastic/agent/server/api.py", line 500, in _rendezvous
    rdzv_info = spec.rdzv_handler.next_rendezvous()
  File "/usr/local/lib/python3.10/dist-packages/torch/distributed/elastic/rendezvous/static_tcp_rendezvous.py", line 67, in next_rendezvous
    self._store = TCPStore(  # type: ignore[call-arg]
RuntimeError: The server socket has failed to listen on any local network address. port: 29500, useIpv6: 0, code: -98, name: EADDRINUSE, message: address already in use
INFO:    Terminating squashfuse_ll after timeout
INFO:    Timeouts can be caused by a running background process
Uncaught exception in compile_worker subprocess
Traceback (most recent call last):
  File "/usr/local/lib/python3.10/dist-packages/torch/_inductor/compile_worker/__main__.py", line 38, in main
    pre_fork_setup()
  File "/usr/local/lib/python3.10/dist-packages/torch/_inductor/async_compile.py", line 62, in pre_fork_setup
  File "/usr/local/lib/python3.10/dist-packages/triton/compiler/compiler.py", line 156, in triton_key
OSError: [Errno 107] Transport endpoint is not connected
Exception ignored in atexit callback: <function dump_compile_times at 0x14ac39e7e290>
Traceback (most recent call last):
  File "/usr/local/lib/python3.10/dist-packages/torch/_dynamo/utils.py", line 446, in dump_compile_times
  File "/usr/local/lib/python3.10/dist-packages/torch/_dynamo/utils.py", line 432, in compile_times
  File "/usr/local/lib/python3.10/dist-packages/torch/_dynamo/utils.py", line 207, in tabulate
  File "<frozen importlib._bootstrap>", line 1027, in _find_and_load
  File "<frozen importlib._bootstrap>", line 1006, in _find_and_load_unlocked
  File "<frozen importlib._bootstrap>", line 688, in _load_unlocked
  File "<frozen importlib._bootstrap_external>", line 879, in exec_module
  File "<frozen importlib._bootstrap_external>", line 1016, in get_code
  File "<frozen importlib._bootstrap_external>", line 1073, in get_data
OSError: [Errno 107] Transport endpoint is not connected: '/usr/local/lib/python3.10/dist-packages/tabulate/__init__.py'
srun: error: g3106: task 0: Exited with exit code 1
