slurmstepd: error: execve():  : No such file or directory
srun: error: g3103: task 0: Exited with exit code 2
[2025-05-06 17:21:15,005] [INFO] [real_accelerator.py:239:get_accelerator] Setting ds_accelerator to cuda (auto detect)
/usr/bin/python3: can't open file '/gscratch/stf/lbc800/mistral-KD/train_scripts/GKD.py': [Errno 2] No such file or directory
/usr/bin/python3: can't open file '/gscratch/stf/lbc800/mistral-KD/train_scripts/GKD.py': [Errno 2] No such file or directory
E0506 17:21:20.605000 41227 torch/distributed/elastic/multiprocessing/api.py:869] failed (exitcode: 2) local_rank: 0 (pid: 43105) of binary: /usr/bin/python3
Traceback (most recent call last):
  File "/usr/local/bin/accelerate", line 8, in <module>
    sys.exit(main())
  File "/usr/local/lib/python3.10/dist-packages/accelerate/commands/accelerate_cli.py", line 50, in main
    args.func(args)
  File "/usr/local/lib/python3.10/dist-packages/accelerate/commands/launch.py", line 1196, in launch_command
    deepspeed_launcher(args)
  File "/usr/local/lib/python3.10/dist-packages/accelerate/commands/launch.py", line 878, in deepspeed_launcher
    distrib_run.run(args)
  File "/usr/local/lib/python3.10/dist-packages/torch/distributed/run.py", line 909, in run
    elastic_launch(
  File "/usr/local/lib/python3.10/dist-packages/torch/distributed/launcher/api.py", line 138, in __call__
    return launch_agent(self._config, self._entrypoint, list(args))
  File "/usr/local/lib/python3.10/dist-packages/torch/distributed/launcher/api.py", line 269, in launch_agent
    raise ChildFailedError(
torch.distributed.elastic.multiprocessing.errors.ChildFailedError: 
============================================================
/gscratch/stf/lbc800/mistral-KD/train_scripts/GKD.py FAILED
------------------------------------------------------------
Failures:
[1]:
  time      : 2025-05-06_17:21:20
  host      : g3103.hyak.local
  rank      : 1 (local_rank: 1)
  exitcode  : 2 (pid: 43106)
  error_file: <N/A>
  traceback : To enable traceback see: https://pytorch.org/docs/stable/elastic/errors.html
------------------------------------------------------------
Root Cause (first observed failure):
[0]:
  time      : 2025-05-06_17:21:20
  host      : g3103.hyak.local
  rank      : 0 (local_rank: 0)
  exitcode  : 2 (pid: 43105)
  error_file: <N/A>
  traceback : To enable traceback see: https://pytorch.org/docs/stable/elastic/errors.html
============================================================
INFO:    Terminating squashfuse_ll after timeout
INFO:    Timeouts can be caused by a running background process
